2021-03-27 13:13:39,265 | DEBUG | proactor_events.py:623| Using proactor: IocpProactor
2021-03-27 13:22:17,837 | ERROR | log.py:224| Internal Server Error: /register
Traceback (most recent call last):
  File "C:\workbench3\learning\django\venv\lib\site-packages\django\db\backends\utils.py", line 84, in _execute
    return self.cursor.execute(sql, params)
  File "C:\workbench3\learning\django\venv\lib\site-packages\django\db\backends\sqlite3\base.py", line 413, in execute
    return Database.Cursor.execute(self, query, params)
sqlite3.IntegrityError: NOT NULL constraint failed: web_app_userprofile.date

The above exception was the direct cause of the following exception:

Traceback (most recent call last):
  File "C:\workbench3\learning\django\venv\lib\site-packages\django\core\handlers\exception.py", line 47, in inner
    response = get_response(request)
  File "C:\workbench3\learning\django\venv\lib\site-packages\django\core\handlers\base.py", line 181, in _get_response
    response = wrapped_callback(request, *callback_args, **callback_kwargs)
  File "C:\workbench3\learning\django\src\python-bootcamp\web_project\web_app\views.py", line 32, in register
    profile.save()
  File "C:\workbench3\learning\django\venv\lib\site-packages\django\db\models\base.py", line 753, in save
    self.save_base(using=using, force_insert=force_insert,
  File "C:\workbench3\learning\django\venv\lib\site-packages\django\db\models\base.py", line 790, in save_base
    updated = self._save_table(
  File "C:\workbench3\learning\django\venv\lib\site-packages\django\db\models\base.py", line 895, in _save_table
    results = self._do_insert(cls._base_manager, using, fields, returning_fields, raw)
  File "C:\workbench3\learning\django\venv\lib\site-packages\django\db\models\base.py", line 933, in _do_insert
    return manager._insert(
  File "C:\workbench3\learning\django\venv\lib\site-packages\django\db\models\manager.py", line 85, in manager_method
    return getattr(self.get_queryset(), name)(*args, **kwargs)
  File "C:\workbench3\learning\django\venv\lib\site-packages\django\db\models\query.py", line 1254, in _insert
    return query.get_compiler(using=using).execute_sql(returning_fields)
  File "C:\workbench3\learning\django\venv\lib\site-packages\django\db\models\sql\compiler.py", line 1397, in execute_sql
    cursor.execute(sql, params)
  File "C:\workbench3\learning\django\venv\lib\site-packages\django\db\backends\utils.py", line 98, in execute
    return super().execute(sql, params)
  File "C:\workbench3\learning\django\venv\lib\site-packages\django\db\backends\utils.py", line 66, in execute
    return self._execute_with_wrappers(sql, params, many=False, executor=self._execute)
  File "C:\workbench3\learning\django\venv\lib\site-packages\django\db\backends\utils.py", line 75, in _execute_with_wrappers
    return executor(sql, params, many, context)
  File "C:\workbench3\learning\django\venv\lib\site-packages\django\db\backends\utils.py", line 84, in _execute
    return self.cursor.execute(sql, params)
  File "C:\workbench3\learning\django\venv\lib\site-packages\django\db\utils.py", line 90, in __exit__
    raise dj_exc_value.with_traceback(traceback) from exc_value
  File "C:\workbench3\learning\django\venv\lib\site-packages\django\db\backends\utils.py", line 84, in _execute
    return self.cursor.execute(sql, params)
  File "C:\workbench3\learning\django\venv\lib\site-packages\django\db\backends\sqlite3\base.py", line 413, in execute
    return Database.Cursor.execute(self, query, params)
django.db.utils.IntegrityError: NOT NULL constraint failed: web_app_userprofile.date
2021-03-27 13:22:17,837 | ERROR | log.py:224| Internal Server Error: /register
Traceback (most recent call last):
  File "C:\workbench3\learning\django\venv\lib\site-packages\django\db\backends\utils.py", line 84, in _execute
    return self.cursor.execute(sql, params)
  File "C:\workbench3\learning\django\venv\lib\site-packages\django\db\backends\sqlite3\base.py", line 413, in execute
    return Database.Cursor.execute(self, query, params)
sqlite3.IntegrityError: NOT NULL constraint failed: web_app_userprofile.date

The above exception was the direct cause of the following exception:

Traceback (most recent call last):
  File "C:\workbench3\learning\django\venv\lib\site-packages\django\core\handlers\exception.py", line 47, in inner
    response = get_response(request)
  File "C:\workbench3\learning\django\venv\lib\site-packages\django\core\handlers\base.py", line 181, in _get_response
    response = wrapped_callback(request, *callback_args, **callback_kwargs)
  File "C:\workbench3\learning\django\src\python-bootcamp\web_project\web_app\views.py", line 32, in register
    profile.save()
  File "C:\workbench3\learning\django\venv\lib\site-packages\django\db\models\base.py", line 753, in save
    self.save_base(using=using, force_insert=force_insert,
  File "C:\workbench3\learning\django\venv\lib\site-packages\django\db\models\base.py", line 790, in save_base
    updated = self._save_table(
  File "C:\workbench3\learning\django\venv\lib\site-packages\django\db\models\base.py", line 895, in _save_table
    results = self._do_insert(cls._base_manager, using, fields, returning_fields, raw)
  File "C:\workbench3\learning\django\venv\lib\site-packages\django\db\models\base.py", line 933, in _do_insert
    return manager._insert(
  File "C:\workbench3\learning\django\venv\lib\site-packages\django\db\models\manager.py", line 85, in manager_method
    return getattr(self.get_queryset(), name)(*args, **kwargs)
  File "C:\workbench3\learning\django\venv\lib\site-packages\django\db\models\query.py", line 1254, in _insert
    return query.get_compiler(using=using).execute_sql(returning_fields)
  File "C:\workbench3\learning\django\venv\lib\site-packages\django\db\models\sql\compiler.py", line 1397, in execute_sql
    cursor.execute(sql, params)
  File "C:\workbench3\learning\django\venv\lib\site-packages\django\db\backends\utils.py", line 98, in execute
    return super().execute(sql, params)
  File "C:\workbench3\learning\django\venv\lib\site-packages\django\db\backends\utils.py", line 66, in execute
    return self._execute_with_wrappers(sql, params, many=False, executor=self._execute)
  File "C:\workbench3\learning\django\venv\lib\site-packages\django\db\backends\utils.py", line 75, in _execute_with_wrappers
    return executor(sql, params, many, context)
  File "C:\workbench3\learning\django\venv\lib\site-packages\django\db\backends\utils.py", line 84, in _execute
    return self.cursor.execute(sql, params)
  File "C:\workbench3\learning\django\venv\lib\site-packages\django\db\utils.py", line 90, in __exit__
    raise dj_exc_value.with_traceback(traceback) from exc_value
  File "C:\workbench3\learning\django\venv\lib\site-packages\django\db\backends\utils.py", line 84, in _execute
    return self.cursor.execute(sql, params)
  File "C:\workbench3\learning\django\venv\lib\site-packages\django\db\backends\sqlite3\base.py", line 413, in execute
    return Database.Cursor.execute(self, query, params)
django.db.utils.IntegrityError: NOT NULL constraint failed: web_app_userprofile.date
2021-03-27 13:22:17,848 | ERROR | basehttp.py:157| "POST /register HTTP/1.1" 500 149613
2021-03-27 13:22:17,848 | ERROR | basehttp.py:157| "POST /register HTTP/1.1" 500 149613
