Using proactor: IocpProactor
Using proactor: IocpProactor
Using proactor: IocpProactor
Using proactor: IocpProactor
Using proactor: IocpProactor
Using proactor: IocpProactor
Using proactor: IocpProactor
Using proactor: IocpProactor
Using proactor: IocpProactor
STREAM b'IHDR' 16 13
STREAM b'IDAT' 41 415069
Importing BlpImagePlugin
Importing BmpImagePlugin
Importing BufrStubImagePlugin
Importing CurImagePlugin
Importing DcxImagePlugin
Importing DdsImagePlugin
Importing EpsImagePlugin
Importing FitsStubImagePlugin
Importing FliImagePlugin
Importing FpxImagePlugin
Image: failed to import FpxImagePlugin: No module named 'olefile'
Importing FtexImagePlugin
Importing GbrImagePlugin
Importing GifImagePlugin
Importing GribStubImagePlugin
Importing Hdf5StubImagePlugin
Importing IcnsImagePlugin
Importing IcoImagePlugin
Importing ImImagePlugin
Importing ImtImagePlugin
Importing IptcImagePlugin
Importing JpegImagePlugin
Importing Jpeg2KImagePlugin
Importing McIdasImagePlugin
Importing MicImagePlugin
Image: failed to import MicImagePlugin: No module named 'olefile'
Importing MpegImagePlugin
Importing MpoImagePlugin
Importing MspImagePlugin
Importing PalmImagePlugin
Importing PcdImagePlugin
Importing PcxImagePlugin
Importing PdfImagePlugin
Importing PixarImagePlugin
Importing PngImagePlugin
Importing PpmImagePlugin
Importing PsdImagePlugin
Importing SgiImagePlugin
Importing SpiderImagePlugin
Importing SunImagePlugin
Importing TgaImagePlugin
Importing TiffImagePlugin
Importing WebPImagePlugin
Importing WmfImagePlugin
Importing XbmImagePlugin
Importing XpmImagePlugin
Importing XVThumbImagePlugin
Using proactor: IocpProactor
Using proactor: IocpProactor
Using proactor: IocpProactor
Internal Server Error: /vacation_grid/
Traceback (most recent call last):
  File "C:\Users\acer\AppData\Local\Programs\Python\Python38-32\lib\site-packages\django\core\handlers\exception.py", line 47, in inner
    response = get_response(request)
  File "C:\Users\acer\AppData\Local\Programs\Python\Python38-32\lib\site-packages\django\core\handlers\base.py", line 181, in _get_response
    response = wrapped_callback(request, *callback_args, **callback_kwargs)
  File "X:\New_workbench\Project_PI\src\python-final\final_project\final_app\views.py", line 252, in vacation_grid
    vacations = Vacation.objects.all().filter(user_id=user_id).all()
  File "C:\Users\acer\AppData\Local\Programs\Python\Python38-32\lib\site-packages\django\db\models\query.py", line 942, in filter
    return self._filter_or_exclude(False, *args, **kwargs)
  File "C:\Users\acer\AppData\Local\Programs\Python\Python38-32\lib\site-packages\django\db\models\query.py", line 962, in _filter_or_exclude
    clone._filter_or_exclude_inplace(negate, *args, **kwargs)
  File "C:\Users\acer\AppData\Local\Programs\Python\Python38-32\lib\site-packages\django\db\models\query.py", line 969, in _filter_or_exclude_inplace
    self._query.add_q(Q(*args, **kwargs))
  File "C:\Users\acer\AppData\Local\Programs\Python\Python38-32\lib\site-packages\django\db\models\sql\query.py", line 1358, in add_q
    clause, _ = self._add_q(q_object, self.used_aliases)
  File "C:\Users\acer\AppData\Local\Programs\Python\Python38-32\lib\site-packages\django\db\models\sql\query.py", line 1377, in _add_q
    child_clause, needed_inner = self.build_filter(
  File "C:\Users\acer\AppData\Local\Programs\Python\Python38-32\lib\site-packages\django\db\models\sql\query.py", line 1258, in build_filter
    lookups, parts, reffed_expression = self.solve_lookup_type(arg)
  File "C:\Users\acer\AppData\Local\Programs\Python\Python38-32\lib\site-packages\django\db\models\sql\query.py", line 1084, in solve_lookup_type
    _, field, _, lookup_parts = self.names_to_path(lookup_splitted, self.get_meta())
  File "C:\Users\acer\AppData\Local\Programs\Python\Python38-32\lib\site-packages\django\db\models\sql\query.py", line 1481, in names_to_path
    raise FieldError("Cannot resolve keyword '%s' into field. "
django.core.exceptions.FieldError: Cannot resolve keyword 'user_id' into field. Choices are: date_from, date_to, description, duration, employee, employee_id, id
Internal Server Error: /vacation_grid/
Traceback (most recent call last):
  File "C:\Users\acer\AppData\Local\Programs\Python\Python38-32\lib\site-packages\django\core\handlers\exception.py", line 47, in inner
    response = get_response(request)
  File "C:\Users\acer\AppData\Local\Programs\Python\Python38-32\lib\site-packages\django\core\handlers\base.py", line 181, in _get_response
    response = wrapped_callback(request, *callback_args, **callback_kwargs)
  File "X:\New_workbench\Project_PI\src\python-final\final_project\final_app\views.py", line 252, in vacation_grid
    vacations = Vacation.objects.all().filter(user_id=user_id).all()
  File "C:\Users\acer\AppData\Local\Programs\Python\Python38-32\lib\site-packages\django\db\models\query.py", line 942, in filter
    return self._filter_or_exclude(False, *args, **kwargs)
  File "C:\Users\acer\AppData\Local\Programs\Python\Python38-32\lib\site-packages\django\db\models\query.py", line 962, in _filter_or_exclude
    clone._filter_or_exclude_inplace(negate, *args, **kwargs)
  File "C:\Users\acer\AppData\Local\Programs\Python\Python38-32\lib\site-packages\django\db\models\query.py", line 969, in _filter_or_exclude_inplace
    self._query.add_q(Q(*args, **kwargs))
  File "C:\Users\acer\AppData\Local\Programs\Python\Python38-32\lib\site-packages\django\db\models\sql\query.py", line 1358, in add_q
    clause, _ = self._add_q(q_object, self.used_aliases)
  File "C:\Users\acer\AppData\Local\Programs\Python\Python38-32\lib\site-packages\django\db\models\sql\query.py", line 1377, in _add_q
    child_clause, needed_inner = self.build_filter(
  File "C:\Users\acer\AppData\Local\Programs\Python\Python38-32\lib\site-packages\django\db\models\sql\query.py", line 1258, in build_filter
    lookups, parts, reffed_expression = self.solve_lookup_type(arg)
  File "C:\Users\acer\AppData\Local\Programs\Python\Python38-32\lib\site-packages\django\db\models\sql\query.py", line 1084, in solve_lookup_type
    _, field, _, lookup_parts = self.names_to_path(lookup_splitted, self.get_meta())
  File "C:\Users\acer\AppData\Local\Programs\Python\Python38-32\lib\site-packages\django\db\models\sql\query.py", line 1481, in names_to_path
    raise FieldError("Cannot resolve keyword '%s' into field. "
django.core.exceptions.FieldError: Cannot resolve keyword 'user_id' into field. Choices are: date_from, date_to, description, duration, employee, employee_id, id
"POST /vacation_grid/ HTTP/1.1" 500 103654
"POST /vacation_grid/ HTTP/1.1" 500 103654
Internal Server Error: /vacation_grid/
Traceback (most recent call last):
  File "C:\Users\acer\AppData\Local\Programs\Python\Python38-32\lib\site-packages\django\core\handlers\exception.py", line 47, in inner
    response = get_response(request)
  File "C:\Users\acer\AppData\Local\Programs\Python\Python38-32\lib\site-packages\django\core\handlers\base.py", line 181, in _get_response
    response = wrapped_callback(request, *callback_args, **callback_kwargs)
  File "X:\New_workbench\Project_PI\src\python-final\final_project\final_app\views.py", line 252, in vacation_grid
    vacations = Vacation.objects.all().filter(user_id=user_id).all()
  File "C:\Users\acer\AppData\Local\Programs\Python\Python38-32\lib\site-packages\django\db\models\query.py", line 942, in filter
    return self._filter_or_exclude(False, *args, **kwargs)
  File "C:\Users\acer\AppData\Local\Programs\Python\Python38-32\lib\site-packages\django\db\models\query.py", line 962, in _filter_or_exclude
    clone._filter_or_exclude_inplace(negate, *args, **kwargs)
  File "C:\Users\acer\AppData\Local\Programs\Python\Python38-32\lib\site-packages\django\db\models\query.py", line 969, in _filter_or_exclude_inplace
    self._query.add_q(Q(*args, **kwargs))
  File "C:\Users\acer\AppData\Local\Programs\Python\Python38-32\lib\site-packages\django\db\models\sql\query.py", line 1358, in add_q
    clause, _ = self._add_q(q_object, self.used_aliases)
  File "C:\Users\acer\AppData\Local\Programs\Python\Python38-32\lib\site-packages\django\db\models\sql\query.py", line 1377, in _add_q
    child_clause, needed_inner = self.build_filter(
  File "C:\Users\acer\AppData\Local\Programs\Python\Python38-32\lib\site-packages\django\db\models\sql\query.py", line 1258, in build_filter
    lookups, parts, reffed_expression = self.solve_lookup_type(arg)
  File "C:\Users\acer\AppData\Local\Programs\Python\Python38-32\lib\site-packages\django\db\models\sql\query.py", line 1084, in solve_lookup_type
    _, field, _, lookup_parts = self.names_to_path(lookup_splitted, self.get_meta())
  File "C:\Users\acer\AppData\Local\Programs\Python\Python38-32\lib\site-packages\django\db\models\sql\query.py", line 1481, in names_to_path
    raise FieldError("Cannot resolve keyword '%s' into field. "
django.core.exceptions.FieldError: Cannot resolve keyword 'user_id' into field. Choices are: date_from, date_to, description, duration, employee, employee_id, id
Internal Server Error: /vacation_grid/
Traceback (most recent call last):
  File "C:\Users\acer\AppData\Local\Programs\Python\Python38-32\lib\site-packages\django\core\handlers\exception.py", line 47, in inner
    response = get_response(request)
  File "C:\Users\acer\AppData\Local\Programs\Python\Python38-32\lib\site-packages\django\core\handlers\base.py", line 181, in _get_response
    response = wrapped_callback(request, *callback_args, **callback_kwargs)
  File "X:\New_workbench\Project_PI\src\python-final\final_project\final_app\views.py", line 252, in vacation_grid
    vacations = Vacation.objects.all().filter(user_id=user_id).all()
  File "C:\Users\acer\AppData\Local\Programs\Python\Python38-32\lib\site-packages\django\db\models\query.py", line 942, in filter
    return self._filter_or_exclude(False, *args, **kwargs)
  File "C:\Users\acer\AppData\Local\Programs\Python\Python38-32\lib\site-packages\django\db\models\query.py", line 962, in _filter_or_exclude
    clone._filter_or_exclude_inplace(negate, *args, **kwargs)
  File "C:\Users\acer\AppData\Local\Programs\Python\Python38-32\lib\site-packages\django\db\models\query.py", line 969, in _filter_or_exclude_inplace
    self._query.add_q(Q(*args, **kwargs))
  File "C:\Users\acer\AppData\Local\Programs\Python\Python38-32\lib\site-packages\django\db\models\sql\query.py", line 1358, in add_q
    clause, _ = self._add_q(q_object, self.used_aliases)
  File "C:\Users\acer\AppData\Local\Programs\Python\Python38-32\lib\site-packages\django\db\models\sql\query.py", line 1377, in _add_q
    child_clause, needed_inner = self.build_filter(
  File "C:\Users\acer\AppData\Local\Programs\Python\Python38-32\lib\site-packages\django\db\models\sql\query.py", line 1258, in build_filter
    lookups, parts, reffed_expression = self.solve_lookup_type(arg)
  File "C:\Users\acer\AppData\Local\Programs\Python\Python38-32\lib\site-packages\django\db\models\sql\query.py", line 1084, in solve_lookup_type
    _, field, _, lookup_parts = self.names_to_path(lookup_splitted, self.get_meta())
  File "C:\Users\acer\AppData\Local\Programs\Python\Python38-32\lib\site-packages\django\db\models\sql\query.py", line 1481, in names_to_path
    raise FieldError("Cannot resolve keyword '%s' into field. "
django.core.exceptions.FieldError: Cannot resolve keyword 'user_id' into field. Choices are: date_from, date_to, description, duration, employee, employee_id, id
"POST /vacation_grid/ HTTP/1.1" 500 103652
"POST /vacation_grid/ HTTP/1.1" 500 103652
Internal Server Error: /vacation_grid/
Traceback (most recent call last):
  File "C:\Users\acer\AppData\Local\Programs\Python\Python38-32\lib\site-packages\django\core\handlers\exception.py", line 47, in inner
    response = get_response(request)
  File "C:\Users\acer\AppData\Local\Programs\Python\Python38-32\lib\site-packages\django\core\handlers\base.py", line 181, in _get_response
    response = wrapped_callback(request, *callback_args, **callback_kwargs)
  File "X:\New_workbench\Project_PI\src\python-final\final_project\final_app\views.py", line 252, in vacation_grid
    vacations = Vacation.objects.all().filter(user_id=user_id).all()
  File "C:\Users\acer\AppData\Local\Programs\Python\Python38-32\lib\site-packages\django\db\models\query.py", line 942, in filter
    return self._filter_or_exclude(False, *args, **kwargs)
  File "C:\Users\acer\AppData\Local\Programs\Python\Python38-32\lib\site-packages\django\db\models\query.py", line 962, in _filter_or_exclude
    clone._filter_or_exclude_inplace(negate, *args, **kwargs)
  File "C:\Users\acer\AppData\Local\Programs\Python\Python38-32\lib\site-packages\django\db\models\query.py", line 969, in _filter_or_exclude_inplace
    self._query.add_q(Q(*args, **kwargs))
  File "C:\Users\acer\AppData\Local\Programs\Python\Python38-32\lib\site-packages\django\db\models\sql\query.py", line 1358, in add_q
    clause, _ = self._add_q(q_object, self.used_aliases)
  File "C:\Users\acer\AppData\Local\Programs\Python\Python38-32\lib\site-packages\django\db\models\sql\query.py", line 1377, in _add_q
    child_clause, needed_inner = self.build_filter(
  File "C:\Users\acer\AppData\Local\Programs\Python\Python38-32\lib\site-packages\django\db\models\sql\query.py", line 1258, in build_filter
    lookups, parts, reffed_expression = self.solve_lookup_type(arg)
  File "C:\Users\acer\AppData\Local\Programs\Python\Python38-32\lib\site-packages\django\db\models\sql\query.py", line 1084, in solve_lookup_type
    _, field, _, lookup_parts = self.names_to_path(lookup_splitted, self.get_meta())
  File "C:\Users\acer\AppData\Local\Programs\Python\Python38-32\lib\site-packages\django\db\models\sql\query.py", line 1481, in names_to_path
    raise FieldError("Cannot resolve keyword '%s' into field. "
django.core.exceptions.FieldError: Cannot resolve keyword 'user_id' into field. Choices are: date_from, date_to, description, duration, employee, employee_id, id
Internal Server Error: /vacation_grid/
Traceback (most recent call last):
  File "C:\Users\acer\AppData\Local\Programs\Python\Python38-32\lib\site-packages\django\core\handlers\exception.py", line 47, in inner
    response = get_response(request)
  File "C:\Users\acer\AppData\Local\Programs\Python\Python38-32\lib\site-packages\django\core\handlers\base.py", line 181, in _get_response
    response = wrapped_callback(request, *callback_args, **callback_kwargs)
  File "X:\New_workbench\Project_PI\src\python-final\final_project\final_app\views.py", line 252, in vacation_grid
    vacations = Vacation.objects.all().filter(user_id=user_id).all()
  File "C:\Users\acer\AppData\Local\Programs\Python\Python38-32\lib\site-packages\django\db\models\query.py", line 942, in filter
    return self._filter_or_exclude(False, *args, **kwargs)
  File "C:\Users\acer\AppData\Local\Programs\Python\Python38-32\lib\site-packages\django\db\models\query.py", line 962, in _filter_or_exclude
    clone._filter_or_exclude_inplace(negate, *args, **kwargs)
  File "C:\Users\acer\AppData\Local\Programs\Python\Python38-32\lib\site-packages\django\db\models\query.py", line 969, in _filter_or_exclude_inplace
    self._query.add_q(Q(*args, **kwargs))
  File "C:\Users\acer\AppData\Local\Programs\Python\Python38-32\lib\site-packages\django\db\models\sql\query.py", line 1358, in add_q
    clause, _ = self._add_q(q_object, self.used_aliases)
  File "C:\Users\acer\AppData\Local\Programs\Python\Python38-32\lib\site-packages\django\db\models\sql\query.py", line 1377, in _add_q
    child_clause, needed_inner = self.build_filter(
  File "C:\Users\acer\AppData\Local\Programs\Python\Python38-32\lib\site-packages\django\db\models\sql\query.py", line 1258, in build_filter
    lookups, parts, reffed_expression = self.solve_lookup_type(arg)
  File "C:\Users\acer\AppData\Local\Programs\Python\Python38-32\lib\site-packages\django\db\models\sql\query.py", line 1084, in solve_lookup_type
    _, field, _, lookup_parts = self.names_to_path(lookup_splitted, self.get_meta())
  File "C:\Users\acer\AppData\Local\Programs\Python\Python38-32\lib\site-packages\django\db\models\sql\query.py", line 1481, in names_to_path
    raise FieldError("Cannot resolve keyword '%s' into field. "
django.core.exceptions.FieldError: Cannot resolve keyword 'user_id' into field. Choices are: date_from, date_to, description, duration, employee, employee_id, id
"POST /vacation_grid/ HTTP/1.1" 500 103652
"POST /vacation_grid/ HTTP/1.1" 500 103652
Using proactor: IocpProactor
Using proactor: IocpProactor
Internal Server Error: /vacation_grid/
Traceback (most recent call last):
  File "C:\Users\acer\AppData\Local\Programs\Python\Python38-32\lib\site-packages\django\core\handlers\exception.py", line 47, in inner
    response = get_response(request)
  File "C:\Users\acer\AppData\Local\Programs\Python\Python38-32\lib\site-packages\django\core\handlers\base.py", line 181, in _get_response
    response = wrapped_callback(request, *callback_args, **callback_kwargs)
  File "X:\New_workbench\Project_PI\src\python-final\final_project\final_app\views.py", line 252, in vacation_grid
    vacations = Vacation.objects.all().filter(topic_id=topic_id).all()
  File "C:\Users\acer\AppData\Local\Programs\Python\Python38-32\lib\site-packages\django\db\models\query.py", line 942, in filter
    return self._filter_or_exclude(False, *args, **kwargs)
  File "C:\Users\acer\AppData\Local\Programs\Python\Python38-32\lib\site-packages\django\db\models\query.py", line 962, in _filter_or_exclude
    clone._filter_or_exclude_inplace(negate, *args, **kwargs)
  File "C:\Users\acer\AppData\Local\Programs\Python\Python38-32\lib\site-packages\django\db\models\query.py", line 969, in _filter_or_exclude_inplace
    self._query.add_q(Q(*args, **kwargs))
  File "C:\Users\acer\AppData\Local\Programs\Python\Python38-32\lib\site-packages\django\db\models\sql\query.py", line 1358, in add_q
    clause, _ = self._add_q(q_object, self.used_aliases)
  File "C:\Users\acer\AppData\Local\Programs\Python\Python38-32\lib\site-packages\django\db\models\sql\query.py", line 1377, in _add_q
    child_clause, needed_inner = self.build_filter(
  File "C:\Users\acer\AppData\Local\Programs\Python\Python38-32\lib\site-packages\django\db\models\sql\query.py", line 1258, in build_filter
    lookups, parts, reffed_expression = self.solve_lookup_type(arg)
  File "C:\Users\acer\AppData\Local\Programs\Python\Python38-32\lib\site-packages\django\db\models\sql\query.py", line 1084, in solve_lookup_type
    _, field, _, lookup_parts = self.names_to_path(lookup_splitted, self.get_meta())
  File "C:\Users\acer\AppData\Local\Programs\Python\Python38-32\lib\site-packages\django\db\models\sql\query.py", line 1481, in names_to_path
    raise FieldError("Cannot resolve keyword '%s' into field. "
django.core.exceptions.FieldError: Cannot resolve keyword 'topic_id' into field. Choices are: date_from, date_to, description, duration, employee, employee_id, id
Internal Server Error: /vacation_grid/
Traceback (most recent call last):
  File "C:\Users\acer\AppData\Local\Programs\Python\Python38-32\lib\site-packages\django\core\handlers\exception.py", line 47, in inner
    response = get_response(request)
  File "C:\Users\acer\AppData\Local\Programs\Python\Python38-32\lib\site-packages\django\core\handlers\base.py", line 181, in _get_response
    response = wrapped_callback(request, *callback_args, **callback_kwargs)
  File "X:\New_workbench\Project_PI\src\python-final\final_project\final_app\views.py", line 252, in vacation_grid
    vacations = Vacation.objects.all().filter(topic_id=topic_id).all()
  File "C:\Users\acer\AppData\Local\Programs\Python\Python38-32\lib\site-packages\django\db\models\query.py", line 942, in filter
    return self._filter_or_exclude(False, *args, **kwargs)
  File "C:\Users\acer\AppData\Local\Programs\Python\Python38-32\lib\site-packages\django\db\models\query.py", line 962, in _filter_or_exclude
    clone._filter_or_exclude_inplace(negate, *args, **kwargs)
  File "C:\Users\acer\AppData\Local\Programs\Python\Python38-32\lib\site-packages\django\db\models\query.py", line 969, in _filter_or_exclude_inplace
    self._query.add_q(Q(*args, **kwargs))
  File "C:\Users\acer\AppData\Local\Programs\Python\Python38-32\lib\site-packages\django\db\models\sql\query.py", line 1358, in add_q
    clause, _ = self._add_q(q_object, self.used_aliases)
  File "C:\Users\acer\AppData\Local\Programs\Python\Python38-32\lib\site-packages\django\db\models\sql\query.py", line 1377, in _add_q
    child_clause, needed_inner = self.build_filter(
  File "C:\Users\acer\AppData\Local\Programs\Python\Python38-32\lib\site-packages\django\db\models\sql\query.py", line 1258, in build_filter
    lookups, parts, reffed_expression = self.solve_lookup_type(arg)
  File "C:\Users\acer\AppData\Local\Programs\Python\Python38-32\lib\site-packages\django\db\models\sql\query.py", line 1084, in solve_lookup_type
    _, field, _, lookup_parts = self.names_to_path(lookup_splitted, self.get_meta())
  File "C:\Users\acer\AppData\Local\Programs\Python\Python38-32\lib\site-packages\django\db\models\sql\query.py", line 1481, in names_to_path
    raise FieldError("Cannot resolve keyword '%s' into field. "
django.core.exceptions.FieldError: Cannot resolve keyword 'topic_id' into field. Choices are: date_from, date_to, description, duration, employee, employee_id, id
"POST /vacation_grid/ HTTP/1.1" 500 103725
"POST /vacation_grid/ HTTP/1.1" 500 103725
Using proactor: IocpProactor
Using proactor: IocpProactor
Internal Server Error: /vacation_grid/
Traceback (most recent call last):
  File "C:\Users\acer\AppData\Local\Programs\Python\Python38-32\lib\site-packages\django\core\handlers\exception.py", line 47, in inner
    response = get_response(request)
  File "C:\Users\acer\AppData\Local\Programs\Python\Python38-32\lib\site-packages\django\core\handlers\base.py", line 181, in _get_response
    response = wrapped_callback(request, *callback_args, **callback_kwargs)
  File "X:\New_workbench\Project_PI\src\python-final\final_project\final_app\views.py", line 252, in vacation_grid
    vacations = Vacation.objects.all().filter(user_id=user_id).all()
NameError: name 'user_id' is not defined
Internal Server Error: /vacation_grid/
Traceback (most recent call last):
  File "C:\Users\acer\AppData\Local\Programs\Python\Python38-32\lib\site-packages\django\core\handlers\exception.py", line 47, in inner
    response = get_response(request)
  File "C:\Users\acer\AppData\Local\Programs\Python\Python38-32\lib\site-packages\django\core\handlers\base.py", line 181, in _get_response
    response = wrapped_callback(request, *callback_args, **callback_kwargs)
  File "X:\New_workbench\Project_PI\src\python-final\final_project\final_app\views.py", line 252, in vacation_grid
    vacations = Vacation.objects.all().filter(user_id=user_id).all()
NameError: name 'user_id' is not defined
"POST /vacation_grid/ HTTP/1.1" 500 65420
"POST /vacation_grid/ HTTP/1.1" 500 65420
Index
Index 
warning
ll
Internal Server Error: /vacation_grid/
Traceback (most recent call last):
  File "C:\Users\acer\AppData\Local\Programs\Python\Python38-32\lib\site-packages\django\core\handlers\exception.py", line 47, in inner
    response = get_response(request)
  File "C:\Users\acer\AppData\Local\Programs\Python\Python38-32\lib\site-packages\django\core\handlers\base.py", line 181, in _get_response
    response = wrapped_callback(request, *callback_args, **callback_kwargs)
  File "X:\New_workbench\Project_PI\src\python-final\final_project\final_app\views.py", line 252, in vacation_grid
    vacations = Vacation.objects.all().filter(user_id=user_id).all()
NameError: name 'user_id' is not defined
Internal Server Error: /vacation_grid/
Traceback (most recent call last):
  File "C:\Users\acer\AppData\Local\Programs\Python\Python38-32\lib\site-packages\django\core\handlers\exception.py", line 47, in inner
    response = get_response(request)
  File "C:\Users\acer\AppData\Local\Programs\Python\Python38-32\lib\site-packages\django\core\handlers\base.py", line 181, in _get_response
    response = wrapped_callback(request, *callback_args, **callback_kwargs)
  File "X:\New_workbench\Project_PI\src\python-final\final_project\final_app\views.py", line 252, in vacation_grid
    vacations = Vacation.objects.all().filter(user_id=user_id).all()
NameError: name 'user_id' is not defined
"POST /vacation_grid/ HTTP/1.1" 500 65420
"POST /vacation_grid/ HTTP/1.1" 500 65420
Using proactor: IocpProactor
Internal Server Error: /vacation_grid/
Traceback (most recent call last):
  File "C:\Users\acer\AppData\Local\Programs\Python\Python38-32\lib\site-packages\django\core\handlers\exception.py", line 47, in inner
    response = get_response(request)
  File "C:\Users\acer\AppData\Local\Programs\Python\Python38-32\lib\site-packages\django\core\handlers\base.py", line 181, in _get_response
    response = wrapped_callback(request, *callback_args, **callback_kwargs)
  File "X:\New_workbench\Project_PI\src\python-final\final_project\final_app\views.py", line 252, in vacation_grid
    vacations = Vacation.objects.all().filter(user_id=user_id).all()
  File "C:\Users\acer\AppData\Local\Programs\Python\Python38-32\lib\site-packages\django\db\models\query.py", line 942, in filter
    return self._filter_or_exclude(False, *args, **kwargs)
  File "C:\Users\acer\AppData\Local\Programs\Python\Python38-32\lib\site-packages\django\db\models\query.py", line 962, in _filter_or_exclude
    clone._filter_or_exclude_inplace(negate, *args, **kwargs)
  File "C:\Users\acer\AppData\Local\Programs\Python\Python38-32\lib\site-packages\django\db\models\query.py", line 969, in _filter_or_exclude_inplace
    self._query.add_q(Q(*args, **kwargs))
  File "C:\Users\acer\AppData\Local\Programs\Python\Python38-32\lib\site-packages\django\db\models\sql\query.py", line 1358, in add_q
    clause, _ = self._add_q(q_object, self.used_aliases)
  File "C:\Users\acer\AppData\Local\Programs\Python\Python38-32\lib\site-packages\django\db\models\sql\query.py", line 1377, in _add_q
    child_clause, needed_inner = self.build_filter(
  File "C:\Users\acer\AppData\Local\Programs\Python\Python38-32\lib\site-packages\django\db\models\sql\query.py", line 1258, in build_filter
    lookups, parts, reffed_expression = self.solve_lookup_type(arg)
  File "C:\Users\acer\AppData\Local\Programs\Python\Python38-32\lib\site-packages\django\db\models\sql\query.py", line 1084, in solve_lookup_type
    _, field, _, lookup_parts = self.names_to_path(lookup_splitted, self.get_meta())
  File "C:\Users\acer\AppData\Local\Programs\Python\Python38-32\lib\site-packages\django\db\models\sql\query.py", line 1481, in names_to_path
    raise FieldError("Cannot resolve keyword '%s' into field. "
django.core.exceptions.FieldError: Cannot resolve keyword 'user_id' into field. Choices are: date_from, date_to, description, duration, employee, employee_id, id
Internal Server Error: /vacation_grid/
Traceback (most recent call last):
  File "C:\Users\acer\AppData\Local\Programs\Python\Python38-32\lib\site-packages\django\core\handlers\exception.py", line 47, in inner
    response = get_response(request)
  File "C:\Users\acer\AppData\Local\Programs\Python\Python38-32\lib\site-packages\django\core\handlers\base.py", line 181, in _get_response
    response = wrapped_callback(request, *callback_args, **callback_kwargs)
  File "X:\New_workbench\Project_PI\src\python-final\final_project\final_app\views.py", line 252, in vacation_grid
    vacations = Vacation.objects.all().filter(user_id=user_id).all()
  File "C:\Users\acer\AppData\Local\Programs\Python\Python38-32\lib\site-packages\django\db\models\query.py", line 942, in filter
    return self._filter_or_exclude(False, *args, **kwargs)
  File "C:\Users\acer\AppData\Local\Programs\Python\Python38-32\lib\site-packages\django\db\models\query.py", line 962, in _filter_or_exclude
    clone._filter_or_exclude_inplace(negate, *args, **kwargs)
  File "C:\Users\acer\AppData\Local\Programs\Python\Python38-32\lib\site-packages\django\db\models\query.py", line 969, in _filter_or_exclude_inplace
    self._query.add_q(Q(*args, **kwargs))
  File "C:\Users\acer\AppData\Local\Programs\Python\Python38-32\lib\site-packages\django\db\models\sql\query.py", line 1358, in add_q
    clause, _ = self._add_q(q_object, self.used_aliases)
  File "C:\Users\acer\AppData\Local\Programs\Python\Python38-32\lib\site-packages\django\db\models\sql\query.py", line 1377, in _add_q
    child_clause, needed_inner = self.build_filter(
  File "C:\Users\acer\AppData\Local\Programs\Python\Python38-32\lib\site-packages\django\db\models\sql\query.py", line 1258, in build_filter
    lookups, parts, reffed_expression = self.solve_lookup_type(arg)
  File "C:\Users\acer\AppData\Local\Programs\Python\Python38-32\lib\site-packages\django\db\models\sql\query.py", line 1084, in solve_lookup_type
    _, field, _, lookup_parts = self.names_to_path(lookup_splitted, self.get_meta())
  File "C:\Users\acer\AppData\Local\Programs\Python\Python38-32\lib\site-packages\django\db\models\sql\query.py", line 1481, in names_to_path
    raise FieldError("Cannot resolve keyword '%s' into field. "
django.core.exceptions.FieldError: Cannot resolve keyword 'user_id' into field. Choices are: date_from, date_to, description, duration, employee, employee_id, id
"POST /vacation_grid/ HTTP/1.1" 500 103782
"POST /vacation_grid/ HTTP/1.1" 500 103782
Internal Server Error: /vacation_grid/
Traceback (most recent call last):
  File "C:\Users\acer\AppData\Local\Programs\Python\Python38-32\lib\site-packages\django\core\handlers\exception.py", line 47, in inner
    response = get_response(request)
  File "C:\Users\acer\AppData\Local\Programs\Python\Python38-32\lib\site-packages\django\core\handlers\base.py", line 181, in _get_response
    response = wrapped_callback(request, *callback_args, **callback_kwargs)
  File "X:\New_workbench\Project_PI\src\python-final\final_project\final_app\views.py", line 252, in vacation_grid
    vacations = Vacation.objects.all().filter(user_id=user_id).all()
  File "C:\Users\acer\AppData\Local\Programs\Python\Python38-32\lib\site-packages\django\db\models\query.py", line 942, in filter
    return self._filter_or_exclude(False, *args, **kwargs)
  File "C:\Users\acer\AppData\Local\Programs\Python\Python38-32\lib\site-packages\django\db\models\query.py", line 962, in _filter_or_exclude
    clone._filter_or_exclude_inplace(negate, *args, **kwargs)
  File "C:\Users\acer\AppData\Local\Programs\Python\Python38-32\lib\site-packages\django\db\models\query.py", line 969, in _filter_or_exclude_inplace
    self._query.add_q(Q(*args, **kwargs))
  File "C:\Users\acer\AppData\Local\Programs\Python\Python38-32\lib\site-packages\django\db\models\sql\query.py", line 1358, in add_q
    clause, _ = self._add_q(q_object, self.used_aliases)
  File "C:\Users\acer\AppData\Local\Programs\Python\Python38-32\lib\site-packages\django\db\models\sql\query.py", line 1377, in _add_q
    child_clause, needed_inner = self.build_filter(
  File "C:\Users\acer\AppData\Local\Programs\Python\Python38-32\lib\site-packages\django\db\models\sql\query.py", line 1258, in build_filter
    lookups, parts, reffed_expression = self.solve_lookup_type(arg)
  File "C:\Users\acer\AppData\Local\Programs\Python\Python38-32\lib\site-packages\django\db\models\sql\query.py", line 1084, in solve_lookup_type
    _, field, _, lookup_parts = self.names_to_path(lookup_splitted, self.get_meta())
  File "C:\Users\acer\AppData\Local\Programs\Python\Python38-32\lib\site-packages\django\db\models\sql\query.py", line 1481, in names_to_path
    raise FieldError("Cannot resolve keyword '%s' into field. "
django.core.exceptions.FieldError: Cannot resolve keyword 'user_id' into field. Choices are: date_from, date_to, description, duration, employee, employee_id, id
Internal Server Error: /vacation_grid/
Traceback (most recent call last):
  File "C:\Users\acer\AppData\Local\Programs\Python\Python38-32\lib\site-packages\django\core\handlers\exception.py", line 47, in inner
    response = get_response(request)
  File "C:\Users\acer\AppData\Local\Programs\Python\Python38-32\lib\site-packages\django\core\handlers\base.py", line 181, in _get_response
    response = wrapped_callback(request, *callback_args, **callback_kwargs)
  File "X:\New_workbench\Project_PI\src\python-final\final_project\final_app\views.py", line 252, in vacation_grid
    vacations = Vacation.objects.all().filter(user_id=user_id).all()
  File "C:\Users\acer\AppData\Local\Programs\Python\Python38-32\lib\site-packages\django\db\models\query.py", line 942, in filter
    return self._filter_or_exclude(False, *args, **kwargs)
  File "C:\Users\acer\AppData\Local\Programs\Python\Python38-32\lib\site-packages\django\db\models\query.py", line 962, in _filter_or_exclude
    clone._filter_or_exclude_inplace(negate, *args, **kwargs)
  File "C:\Users\acer\AppData\Local\Programs\Python\Python38-32\lib\site-packages\django\db\models\query.py", line 969, in _filter_or_exclude_inplace
    self._query.add_q(Q(*args, **kwargs))
  File "C:\Users\acer\AppData\Local\Programs\Python\Python38-32\lib\site-packages\django\db\models\sql\query.py", line 1358, in add_q
    clause, _ = self._add_q(q_object, self.used_aliases)
  File "C:\Users\acer\AppData\Local\Programs\Python\Python38-32\lib\site-packages\django\db\models\sql\query.py", line 1377, in _add_q
    child_clause, needed_inner = self.build_filter(
  File "C:\Users\acer\AppData\Local\Programs\Python\Python38-32\lib\site-packages\django\db\models\sql\query.py", line 1258, in build_filter
    lookups, parts, reffed_expression = self.solve_lookup_type(arg)
  File "C:\Users\acer\AppData\Local\Programs\Python\Python38-32\lib\site-packages\django\db\models\sql\query.py", line 1084, in solve_lookup_type
    _, field, _, lookup_parts = self.names_to_path(lookup_splitted, self.get_meta())
  File "C:\Users\acer\AppData\Local\Programs\Python\Python38-32\lib\site-packages\django\db\models\sql\query.py", line 1481, in names_to_path
    raise FieldError("Cannot resolve keyword '%s' into field. "
django.core.exceptions.FieldError: Cannot resolve keyword 'user_id' into field. Choices are: date_from, date_to, description, duration, employee, employee_id, id
"POST /vacation_grid/ HTTP/1.1" 500 103782
"POST /vacation_grid/ HTTP/1.1" 500 103782
Using proactor: IocpProactor
Using proactor: IocpProactor
Internal Server Error: /vacation_grid/
Traceback (most recent call last):
  File "C:\Users\acer\AppData\Local\Programs\Python\Python38-32\lib\site-packages\django\core\handlers\exception.py", line 47, in inner
    response = get_response(request)
  File "C:\Users\acer\AppData\Local\Programs\Python\Python38-32\lib\site-packages\django\core\handlers\base.py", line 181, in _get_response
    response = wrapped_callback(request, *callback_args, **callback_kwargs)
  File "X:\New_workbench\Project_PI\src\python-final\final_project\final_app\views.py", line 266, in vacation_grid
    return HttpResponse(json.dumps(response))
  File "C:\Users\acer\AppData\Local\Programs\Python\Python38-32\lib\json\__init__.py", line 231, in dumps
    return _default_encoder.encode(obj)
  File "C:\Users\acer\AppData\Local\Programs\Python\Python38-32\lib\json\encoder.py", line 199, in encode
    chunks = self.iterencode(o, _one_shot=True)
  File "C:\Users\acer\AppData\Local\Programs\Python\Python38-32\lib\json\encoder.py", line 257, in iterencode
    return _iterencode(o, 0)
  File "C:\Users\acer\AppData\Local\Programs\Python\Python38-32\lib\json\encoder.py", line 179, in default
    raise TypeError(f'Object of type {o.__class__.__name__} '
TypeError: Object of type date is not JSON serializable
Internal Server Error: /vacation_grid/
Traceback (most recent call last):
  File "C:\Users\acer\AppData\Local\Programs\Python\Python38-32\lib\site-packages\django\core\handlers\exception.py", line 47, in inner
    response = get_response(request)
  File "C:\Users\acer\AppData\Local\Programs\Python\Python38-32\lib\site-packages\django\core\handlers\base.py", line 181, in _get_response
    response = wrapped_callback(request, *callback_args, **callback_kwargs)
  File "X:\New_workbench\Project_PI\src\python-final\final_project\final_app\views.py", line 266, in vacation_grid
    return HttpResponse(json.dumps(response))
  File "C:\Users\acer\AppData\Local\Programs\Python\Python38-32\lib\json\__init__.py", line 231, in dumps
    return _default_encoder.encode(obj)
  File "C:\Users\acer\AppData\Local\Programs\Python\Python38-32\lib\json\encoder.py", line 199, in encode
    chunks = self.iterencode(o, _one_shot=True)
  File "C:\Users\acer\AppData\Local\Programs\Python\Python38-32\lib\json\encoder.py", line 257, in iterencode
    return _iterencode(o, 0)
  File "C:\Users\acer\AppData\Local\Programs\Python\Python38-32\lib\json\encoder.py", line 179, in default
    raise TypeError(f'Object of type {o.__class__.__name__} '
TypeError: Object of type date is not JSON serializable
"POST /vacation_grid/ HTTP/1.1" 500 85635
"POST /vacation_grid/ HTTP/1.1" 500 85635
Internal Server Error: /vacation_grid/
Traceback (most recent call last):
  File "C:\Users\acer\AppData\Local\Programs\Python\Python38-32\lib\site-packages\django\core\handlers\exception.py", line 47, in inner
    response = get_response(request)
  File "C:\Users\acer\AppData\Local\Programs\Python\Python38-32\lib\site-packages\django\core\handlers\base.py", line 181, in _get_response
    response = wrapped_callback(request, *callback_args, **callback_kwargs)
  File "X:\New_workbench\Project_PI\src\python-final\final_project\final_app\views.py", line 266, in vacation_grid
    return HttpResponse(json.dumps(response))
  File "C:\Users\acer\AppData\Local\Programs\Python\Python38-32\lib\json\__init__.py", line 231, in dumps
    return _default_encoder.encode(obj)
  File "C:\Users\acer\AppData\Local\Programs\Python\Python38-32\lib\json\encoder.py", line 199, in encode
    chunks = self.iterencode(o, _one_shot=True)
  File "C:\Users\acer\AppData\Local\Programs\Python\Python38-32\lib\json\encoder.py", line 257, in iterencode
    return _iterencode(o, 0)
  File "C:\Users\acer\AppData\Local\Programs\Python\Python38-32\lib\json\encoder.py", line 179, in default
    raise TypeError(f'Object of type {o.__class__.__name__} '
TypeError: Object of type date is not JSON serializable
Internal Server Error: /vacation_grid/
Traceback (most recent call last):
  File "C:\Users\acer\AppData\Local\Programs\Python\Python38-32\lib\site-packages\django\core\handlers\exception.py", line 47, in inner
    response = get_response(request)
  File "C:\Users\acer\AppData\Local\Programs\Python\Python38-32\lib\site-packages\django\core\handlers\base.py", line 181, in _get_response
    response = wrapped_callback(request, *callback_args, **callback_kwargs)
  File "X:\New_workbench\Project_PI\src\python-final\final_project\final_app\views.py", line 266, in vacation_grid
    return HttpResponse(json.dumps(response))
  File "C:\Users\acer\AppData\Local\Programs\Python\Python38-32\lib\json\__init__.py", line 231, in dumps
    return _default_encoder.encode(obj)
  File "C:\Users\acer\AppData\Local\Programs\Python\Python38-32\lib\json\encoder.py", line 199, in encode
    chunks = self.iterencode(o, _one_shot=True)
  File "C:\Users\acer\AppData\Local\Programs\Python\Python38-32\lib\json\encoder.py", line 257, in iterencode
    return _iterencode(o, 0)
  File "C:\Users\acer\AppData\Local\Programs\Python\Python38-32\lib\json\encoder.py", line 179, in default
    raise TypeError(f'Object of type {o.__class__.__name__} '
TypeError: Object of type date is not JSON serializable
"POST /vacation_grid/ HTTP/1.1" 500 85635
"POST /vacation_grid/ HTTP/1.1" 500 85635
Internal Server Error: /vacation_grid/
Traceback (most recent call last):
  File "C:\Users\acer\AppData\Local\Programs\Python\Python38-32\lib\site-packages\django\core\handlers\exception.py", line 47, in inner
    response = get_response(request)
  File "C:\Users\acer\AppData\Local\Programs\Python\Python38-32\lib\site-packages\django\core\handlers\base.py", line 181, in _get_response
    response = wrapped_callback(request, *callback_args, **callback_kwargs)
  File "X:\New_workbench\Project_PI\src\python-final\final_project\final_app\views.py", line 266, in vacation_grid
    return HttpResponse(json.dumps(response))
  File "C:\Users\acer\AppData\Local\Programs\Python\Python38-32\lib\json\__init__.py", line 231, in dumps
    return _default_encoder.encode(obj)
  File "C:\Users\acer\AppData\Local\Programs\Python\Python38-32\lib\json\encoder.py", line 199, in encode
    chunks = self.iterencode(o, _one_shot=True)
  File "C:\Users\acer\AppData\Local\Programs\Python\Python38-32\lib\json\encoder.py", line 257, in iterencode
    return _iterencode(o, 0)
  File "C:\Users\acer\AppData\Local\Programs\Python\Python38-32\lib\json\encoder.py", line 179, in default
    raise TypeError(f'Object of type {o.__class__.__name__} '
TypeError: Object of type date is not JSON serializable
Internal Server Error: /vacation_grid/
Traceback (most recent call last):
  File "C:\Users\acer\AppData\Local\Programs\Python\Python38-32\lib\site-packages\django\core\handlers\exception.py", line 47, in inner
    response = get_response(request)
  File "C:\Users\acer\AppData\Local\Programs\Python\Python38-32\lib\site-packages\django\core\handlers\base.py", line 181, in _get_response
    response = wrapped_callback(request, *callback_args, **callback_kwargs)
  File "X:\New_workbench\Project_PI\src\python-final\final_project\final_app\views.py", line 266, in vacation_grid
    return HttpResponse(json.dumps(response))
  File "C:\Users\acer\AppData\Local\Programs\Python\Python38-32\lib\json\__init__.py", line 231, in dumps
    return _default_encoder.encode(obj)
  File "C:\Users\acer\AppData\Local\Programs\Python\Python38-32\lib\json\encoder.py", line 199, in encode
    chunks = self.iterencode(o, _one_shot=True)
  File "C:\Users\acer\AppData\Local\Programs\Python\Python38-32\lib\json\encoder.py", line 257, in iterencode
    return _iterencode(o, 0)
  File "C:\Users\acer\AppData\Local\Programs\Python\Python38-32\lib\json\encoder.py", line 179, in default
    raise TypeError(f'Object of type {o.__class__.__name__} '
TypeError: Object of type date is not JSON serializable
"POST /vacation_grid/ HTTP/1.1" 500 85633
"POST /vacation_grid/ HTTP/1.1" 500 85633
Internal Server Error: /vacation_grid/
Traceback (most recent call last):
  File "C:\Users\acer\AppData\Local\Programs\Python\Python38-32\lib\site-packages\django\core\handlers\exception.py", line 47, in inner
    response = get_response(request)
  File "C:\Users\acer\AppData\Local\Programs\Python\Python38-32\lib\site-packages\django\core\handlers\base.py", line 181, in _get_response
    response = wrapped_callback(request, *callback_args, **callback_kwargs)
  File "X:\New_workbench\Project_PI\src\python-final\final_project\final_app\views.py", line 266, in vacation_grid
    return HttpResponse(json.dumps(response))
  File "C:\Users\acer\AppData\Local\Programs\Python\Python38-32\lib\json\__init__.py", line 231, in dumps
    return _default_encoder.encode(obj)
  File "C:\Users\acer\AppData\Local\Programs\Python\Python38-32\lib\json\encoder.py", line 199, in encode
    chunks = self.iterencode(o, _one_shot=True)
  File "C:\Users\acer\AppData\Local\Programs\Python\Python38-32\lib\json\encoder.py", line 257, in iterencode
    return _iterencode(o, 0)
  File "C:\Users\acer\AppData\Local\Programs\Python\Python38-32\lib\json\encoder.py", line 179, in default
    raise TypeError(f'Object of type {o.__class__.__name__} '
TypeError: Object of type date is not JSON serializable
Internal Server Error: /vacation_grid/
Traceback (most recent call last):
  File "C:\Users\acer\AppData\Local\Programs\Python\Python38-32\lib\site-packages\django\core\handlers\exception.py", line 47, in inner
    response = get_response(request)
  File "C:\Users\acer\AppData\Local\Programs\Python\Python38-32\lib\site-packages\django\core\handlers\base.py", line 181, in _get_response
    response = wrapped_callback(request, *callback_args, **callback_kwargs)
  File "X:\New_workbench\Project_PI\src\python-final\final_project\final_app\views.py", line 266, in vacation_grid
    return HttpResponse(json.dumps(response))
  File "C:\Users\acer\AppData\Local\Programs\Python\Python38-32\lib\json\__init__.py", line 231, in dumps
    return _default_encoder.encode(obj)
  File "C:\Users\acer\AppData\Local\Programs\Python\Python38-32\lib\json\encoder.py", line 199, in encode
    chunks = self.iterencode(o, _one_shot=True)
  File "C:\Users\acer\AppData\Local\Programs\Python\Python38-32\lib\json\encoder.py", line 257, in iterencode
    return _iterencode(o, 0)
  File "C:\Users\acer\AppData\Local\Programs\Python\Python38-32\lib\json\encoder.py", line 179, in default
    raise TypeError(f'Object of type {o.__class__.__name__} '
TypeError: Object of type date is not JSON serializable
"POST /vacation_grid/ HTTP/1.1" 500 85637
"POST /vacation_grid/ HTTP/1.1" 500 85637
Internal Server Error: /vacation_grid/
Traceback (most recent call last):
  File "C:\Users\acer\AppData\Local\Programs\Python\Python38-32\lib\site-packages\django\core\handlers\exception.py", line 47, in inner
    response = get_response(request)
  File "C:\Users\acer\AppData\Local\Programs\Python\Python38-32\lib\site-packages\django\core\handlers\base.py", line 181, in _get_response
    response = wrapped_callback(request, *callback_args, **callback_kwargs)
  File "X:\New_workbench\Project_PI\src\python-final\final_project\final_app\views.py", line 266, in vacation_grid
    return HttpResponse(json.dumps(response))
  File "C:\Users\acer\AppData\Local\Programs\Python\Python38-32\lib\json\__init__.py", line 231, in dumps
    return _default_encoder.encode(obj)
  File "C:\Users\acer\AppData\Local\Programs\Python\Python38-32\lib\json\encoder.py", line 199, in encode
    chunks = self.iterencode(o, _one_shot=True)
  File "C:\Users\acer\AppData\Local\Programs\Python\Python38-32\lib\json\encoder.py", line 257, in iterencode
    return _iterencode(o, 0)
  File "C:\Users\acer\AppData\Local\Programs\Python\Python38-32\lib\json\encoder.py", line 179, in default
    raise TypeError(f'Object of type {o.__class__.__name__} '
TypeError: Object of type date is not JSON serializable
Internal Server Error: /vacation_grid/
Traceback (most recent call last):
  File "C:\Users\acer\AppData\Local\Programs\Python\Python38-32\lib\site-packages\django\core\handlers\exception.py", line 47, in inner
    response = get_response(request)
  File "C:\Users\acer\AppData\Local\Programs\Python\Python38-32\lib\site-packages\django\core\handlers\base.py", line 181, in _get_response
    response = wrapped_callback(request, *callback_args, **callback_kwargs)
  File "X:\New_workbench\Project_PI\src\python-final\final_project\final_app\views.py", line 266, in vacation_grid
    return HttpResponse(json.dumps(response))
  File "C:\Users\acer\AppData\Local\Programs\Python\Python38-32\lib\json\__init__.py", line 231, in dumps
    return _default_encoder.encode(obj)
  File "C:\Users\acer\AppData\Local\Programs\Python\Python38-32\lib\json\encoder.py", line 199, in encode
    chunks = self.iterencode(o, _one_shot=True)
  File "C:\Users\acer\AppData\Local\Programs\Python\Python38-32\lib\json\encoder.py", line 257, in iterencode
    return _iterencode(o, 0)
  File "C:\Users\acer\AppData\Local\Programs\Python\Python38-32\lib\json\encoder.py", line 179, in default
    raise TypeError(f'Object of type {o.__class__.__name__} '
TypeError: Object of type date is not JSON serializable
"POST /vacation_grid/ HTTP/1.1" 500 85635
"POST /vacation_grid/ HTTP/1.1" 500 85635
Using proactor: IocpProactor
